<?xml version="1.0"?>
<robot name="ur5">
  
  <!-- Base Link -->
  <link name="base_link">
    <visual>
      <geometry>
        <mesh filename="meshes/visual/base.stl" scale="1 1 1"/>
      </geometry>
      <material name="grey">
        <color rgba="0.3 0.3 0.3 1"/>
      </material>
    </visual>
    <collision>
      <geometry>
        <cylinder radius="0.08" length="0.1"/>
      </geometry>
    </collision>
    <inertial>
      <mass value="4.0"/>
      <inertia ixx="0.00443333" ixy="0" ixz="0" iyy="0.00443333" iyz="0" izz="0.0072"/>
    </inertial>
  </link>

  <!-- Shoulder Link -->
  <link name="shoulder_link">
    <visual>
      <geometry>
        <mesh filename="meshes/visual/shoulder.stl" scale="1 1 1"/>
      </geometry>
      <material name="blue">
        <color rgba="0.49 0.678 0.8 1"/>
      </material>
    </visual>
    <collision>
      <geometry>
        <cylinder radius="0.06" length="0.1"/>
      </geometry>
    </collision>
    <inertial>
      <mass value="3.7"/>
      <inertia ixx="0.010267" ixy="0" ixz="0" iyy="0.010267" iyz="0" izz="0.00666"/>
    </inertial>
  </link>

  <joint name="shoulder_pan_joint" type="revolute">
    <parent link="base_link"/>
    <child link="shoulder_link"/>
    <origin xyz="0 0 0.089159" rpy="0 0 0"/>
    <axis xyz="0 0 1"/>
    <limit lower="-6.28" upper="6.28" effort="150" velocity="3.15"/>
    <dynamics damping="0.5" friction="0.1"/>
  </joint>

  <!-- Upper Arm Link -->
  <link name="upper_arm_link">
    <visual>
      <geometry>
        <mesh filename="meshes/visual/upperarm.stl" scale="1 1 1"/>
      </geometry>
      <material name="blue">
        <color rgba="0.49 0.678 0.8 1"/>
      </material>
    </visual>
    <collision>
      <origin xyz="0 0 0.2125" rpy="0 0 0"/>
      <geometry>
        <cylinder radius="0.05" length="0.425"/>
      </geometry>
    </collision>
    <inertial>
      <origin xyz="0 0 0.2125" rpy="0 0 0"/>
      <mass value="8.393"/>
      <inertia ixx="0.2269" ixy="0" ixz="0" iyy="0.2269" iyz="0" izz="0.0151"/>
    </inertial>
  </link>

  <joint name="shoulder_lift_joint" type="revolute">
    <parent link="shoulder_link"/>
    <child link="upper_arm_link"/>
    <origin xyz="0 0.13585 0" rpy="0 1.570796327 0"/>
    <axis xyz="0 1 0"/>
    <limit lower="-6.28" upper="6.28" effort="150" velocity="3.15"/>
    <dynamics damping="0.5" friction="0.1"/>
  </joint>

  <!-- Forearm Link -->
  <link name="forearm_link">
    <visual>
      <geometry>
        <mesh filename="meshes/visual/forearm.stl" scale="1 1 1"/>
      </geometry>
      <material name="blue">
        <color rgba="0.49 0.678 0.8 1"/>
      </material>
    </visual>
    <collision>
      <origin xyz="0 0 0.196125" rpy="0 0 0"/>
      <geometry>
        <cylinder radius="0.045" length="0.39225"/>
      </geometry>
    </collision>
    <inertial>
      <origin xyz="0 0 0.196125" rpy="0 0 0"/>
      <mass value="2.275"/>
      <inertia ixx="0.0494" ixy="0" ixz="0" iyy="0.0494" iyz="0" izz="0.004095"/>
    </inertial>
  </link>

  <joint name="elbow_joint" type="revolute">
    <parent link="upper_arm_link"/>
    <child link="forearm_link"/>
    <origin xyz="0 -0.1197 0.425" rpy="0 0 0"/>
    <axis xyz="0 1 0"/>
    <limit lower="-3.14" upper="3.14" effort="150" velocity="3.15"/>
    <dynamics damping="0.5" friction="0.1"/>
  </joint>

  <!-- Wrist 1 Link -->
  <link name="wrist_1_link">
    <visual>
      <geometry>
        <mesh filename="meshes/visual/wrist1.stl" scale="1 1 1"/>
      </geometry>
      <material name="black">
        <color rgba="0.1 0.1 0.1 1"/>
      </material>
    </visual>
    <collision>
      <geometry>
        <cylinder radius="0.035" length="0.08"/>
      </geometry>
    </collision>
    <inertial>
      <mass value="1.219"/>
      <inertia ixx="0.00256" ixy="0" ixz="0" iyy="0.00256" iyz="0" izz="0.0021942"/>
    </inertial>
  </link>

  <joint name="wrist_1_joint" type="revolute">
    <parent link="forearm_link"/>
    <child link="wrist_1_link"/>
    <origin xyz="0 0 0.39225" rpy="0 1.570796327 0"/>
    <axis xyz="0 1 0"/>
    <limit lower="-6.28" upper="6.28" effort="28" velocity="3.2"/>
    <dynamics damping="0.1" friction="0.05"/>
  </joint>

  <!-- Wrist 2 Link -->
  <link name="wrist_2_link">
    <visual>
      <geometry>
        <mesh filename="meshes/visual/wrist2.stl" scale="1 1 1"/>
      </geometry>
      <material name="black">
        <color rgba="0.1 0.1 0.1 1"/>
      </material>
    </visual>
    <collision>
      <geometry>
        <cylinder radius="0.035" length="0.08"/>
      </geometry>
    </collision>
    <inertial>
      <mass value="1.219"/>
      <inertia ixx="0.00256" ixy="0" ixz="0" iyy="0.00256" iyz="0" izz="0.0021942"/>
    </inertial>
  </link>

  <joint name="wrist_2_joint" type="revolute">
    <parent link="wrist_1_link"/>
    <child link="wrist_2_link"/>
    <origin xyz="0 0.09465 0" rpy="0 0 0"/>
    <axis xyz="0 0 1"/>
    <limit lower="-6.28" upper="6.28" effort="28" velocity="3.2"/>
    <dynamics damping="0.1" friction="0.05"/>
  </joint>

  <!-- Wrist 3 Link -->
  <link name="wrist_3_link">
    <visual>
      <geometry>
        <mesh filename="meshes/visual/wrist3.stl" scale="1 1 1"/>
      </geometry>
      <material name="metal">
        <color rgba="0.7 0.7 0.7 1"/>
      </material>
    </visual>
    <collision>
      <geometry>
        <cylinder radius="0.03" length="0.06"/>
      </geometry>
    </collision>
    <inertial>
      <mass value="0.1879"/>
      <inertia ixx="0.000132" ixy="0" ixz="0" iyy="0.000132" iyz="0" izz="0.000132"/>
    </inertial>
  </link>

  <joint name="wrist_3_joint" type="revolute">
    <parent link="wrist_2_link"/>
    <child link="wrist_3_link"/>
    <origin xyz="0 0 0.09465" rpy="0 0 0"/>
    <axis xyz="0 1 0"/>
    <limit lower="-6.28" upper="6.28" effort="28" velocity="3.2"/>
    <dynamics damping="0.1" friction="0.05"/>
  </joint>

</robot>
